<?xml version="1.0" encoding="utf-8"?>
<!-- This URDF was automatically created by SolidWorks to URDF Exporter! Originally created by Stephen Brawner (brawner@gmail.com) 
     Commit Version: 1.5.1-0-g916b5db  Build Version: 1.5.7152.31018
     For more information, please see http://wiki.ros.org/sw_urdf_exporter -->
<robot
  name="Model_ver_2">
  <link
    name="link0">
    <inertial>
      <origin
        xyz="-0.029156 -3.7241E-08 0.093452"
        rpy="0 0 0" />
      <mass
        value="11.427" />
      <inertia
        ixx="0.054316"
        ixy="9.3388E-06"
        ixz="0.0017771"
        iyy="0.078459"
        iyz="4.1486E-08"
        izz="0.072518" />
    </inertial>
    <visual>
      <origin
        xyz="0 0 0"
        rpy="0 0 0" />
      <geometry>
        <mesh
          filename="package://Model_ver_2/meshes/link0.STL" />
      </geometry>
      <material
        name="">
        <color
          rgba="0.19216 0.20392 0.20392 1" />
      </material>
    </visual>
    <collision>
      <origin
        xyz="0 0 0"
        rpy="0 0 0" />
      <geometry>
        <mesh
          filename="package://Model_ver_2/meshes/link0.STL" />
      </geometry>
    </collision>
  </link>
  <link
    name="link1">
    <inertial>
      <origin
        xyz="-0.0034781 0.00147 0.079902"
        rpy="0 0 0" />
      <mass
        value="4.8666" />
      <inertia
        ixx="0.029501"
        ixy="-0.00010831"
        ixz="-0.0011109"
        iyy="0.020888"
        iyz="-0.00056902"
        izz="0.023735" />
    </inertial>
    <visual>
      <origin
        xyz="0 0 0"
        rpy="0 0 0" />
      <geometry>
        <mesh
          filename="package://Model_ver_2/meshes/link1.STL" />
      </geometry>
      <material
        name="">
        <color
          rgba="1 1 1 1" />
      </material>
    </visual>
    <collision>
      <origin
        xyz="0 0 0"
        rpy="0 0 0" />
      <geometry>
        <mesh
          filename="package://Model_ver_2/meshes/link1.STL" />
      </geometry>
    </collision>
  </link>
  <joint
    name="joint1"
    type="revolute">
    <origin
      xyz="0 0 0.174"
      rpy="0 0 -0.0058001" />
    <parent
      link="link0" />
    <child
      link="link1" />
    <axis
      xyz="0 0 1" />
    <limit
      lower="-2.9671"
      upper="2.9671"
      effort="0"
      velocity="530" />
  </joint>
  <link
    name="link2">
    <inertial>
      <origin
        xyz="0.11386 0.010217 0.00088642"
        rpy="0 0 0" />
      <mass
        value="5.5534" />
      <inertia
        ixx="0.020296"
        ixy="-3.4712E-05"
        ixz="0.00052916"
        iyy="0.057887"
        iyz="6.3838E-05"
        izz="0.046863" />
    </inertial>
    <visual>
      <origin
        xyz="0 0 0"
        rpy="0 0 0" />
      <geometry>
        <mesh
          filename="package://Model_ver_2/meshes/link2.STL" />
      </geometry>
      <material
        name="">
        <color
          rgba="1 1 1 1" />
      </material>
    </visual>
    <collision>
      <origin
        xyz="0 0 0"
        rpy="0 0 0" />
      <geometry>
        <mesh
          filename="package://Model_ver_2/meshes/link2.STL" />
      </geometry>
    </collision>
  </link>
  <joint
    name="joint2"
    type="revolute">
    <origin
      xyz="0.02 0 0.171"
      rpy="1.5708 0 0" />
    <parent
      link="link1" />
    <child
      link="link2" />
    <axis
      xyz="0 0 -1" />
    <limit
      lower="-0.8727"
      upper="2.9671"
      effort="0"
      velocity="529" />
  </joint>
  <link
    name="link3">
    <inertial>
      <origin
        xyz="0.027328 0.0054178 -0.00022893"
        rpy="0 0 0" />
      <mass
        value="2.4036" />
      <inertia
        ixx="0.0040082"
        ixy="-0.00049774"
        ixz="-1.6163E-05"
        iyy="0.0070959"
        iyz="-1.2375E-06"
        izz="0.0073491" />
    </inertial>
    <visual>
      <origin
        xyz="0 0 0"
        rpy="0 0 0" />
      <geometry>
        <mesh
          filename="package://Model_ver_2/meshes/link3.STL" />
      </geometry>
      <material
        name="">
        <color
          rgba="1 1 1 1" />
      </material>
    </visual>
    <collision>
      <origin
        xyz="0 0 0"
        rpy="0 0 0" />
      <geometry>
        <mesh
          filename="package://Model_ver_2/meshes/link3.STL" />
      </geometry>
    </collision>
  </link>
  <joint
    name="joint3"
    type="revolute">
    <origin
      xyz="0.25975 -0.011454 0"
      rpy="0 0 0" />
    <parent
      link="link2" />
    <child
      link="link3" />
    <axis
      xyz="0 0 -1" />
    <limit
      lower="-2.7053"
      upper="1.9199"
      effort="0"
      velocity="538" />
  </joint>
  <link
    name="link4">
    <inertial>
      <origin
        xyz="0.001658 -0.0015006 0.065547"
        rpy="0 0 0" />
      <mass
        value="1.5627" />
      <inertia
        ixx="0.0050988"
        ixy="0.00016466"
        ixz="9.5395E-06"
        iyy="0.0036685"
        iyz="0.00034095"
        izz="0.0032277" />
    </inertial>
    <visual>
      <origin
        xyz="0 0 0"
        rpy="0 0 0" />
      <geometry>
        <mesh
          filename="package://Model_ver_2/meshes/link4.STL" />
      </geometry>
      <material
        name="">
        <color
          rgba="1 1 1 1" />
      </material>
    </visual>
    <collision>
      <origin
        xyz="0 0 0"
        rpy="0 0 0" />
      <geometry>
        <mesh
          filename="package://Model_ver_2/meshes/link4.STL" />
      </geometry>
    </collision>
  </link>
  <joint
    name="joint4"
    type="revolute">
    <origin
      xyz="0.11605 0.0095565 0"
      rpy="1.5708 0.064127 1.4803" />
    <parent
      link="link3" />
    <child
      link="link4" />
    <axis
      xyz="0 0 1" />
    <limit
      lower="-3.0543"
      upper="3.0543"
      effort="0"
      velocity="600" />
  </joint>
  <link
    name="link5">
    <inertial>
      <origin
        xyz="2.4963E-06 0.0047127 -0.00021819"
        rpy="0 0 0" />
      <mass
        value="0.82974" />
      <inertia
        ixx="0.001114"
        ixy="7.5541E-08"
        ixz="6.3282E-08"
        iyy="0.00074364"
        iyz="8.805E-06"
        izz="0.0010204" />
    </inertial>
    <visual>
      <origin
        xyz="0 0 0"
        rpy="0 0 0" />
      <geometry>
        <mesh
          filename="package://Model_ver_2/meshes/link5.STL" />
      </geometry>
      <material
        name="">
        <color
          rgba="1 1 1 1" />
      </material>
    </visual>
    <collision>
      <origin
        xyz="0 0 0"
        rpy="0 0 0" />
      <geometry>
        <mesh
          filename="package://Model_ver_2/meshes/link5.STL" />
      </geometry>
    </collision>
  </link>
  <joint
    name="joint5"
    type="revolute">
    <origin
      xyz="0 0 0.14528"
      rpy="1.5708 0.0078556 -3.076" />
    <parent
      link="link4" />
    <child
      link="link5" />
    <axis
      xyz="0 0 -1" />
    <limit
      lower="-2.0945"
      upper="2.0945"
      effort="0"
      velocity="600" />
  </joint>
  <link
    name="link6">
    <inertial>
      <origin
        xyz="-9.9951E-06 4.8931E-06 0.0082566"
        rpy="0 0 0" />
      <mass
        value="0.022711" />
      <inertia
        ixx="4.2021E-06"
        ixy="5.2507E-12"
        ixz="4.7543E-10"
        iyy="4.202E-06"
        iyz="6.1228E-10"
        izz="7.8382E-06" />
    </inertial>
    <visual>
      <origin
        xyz="0 0 0"
        rpy="0 0 0" />
      <geometry>
        <mesh
          filename="package://Model_ver_2/meshes/link6.STL" />
      </geometry>
      <material
        name="">
        <color
          rgba="0.19216 0.20392 0.20392 1" />
      </material>
    </visual>
    <collision>
      <origin
        xyz="0 0 0"
        rpy="0 0 0" />
      <geometry>
        <mesh
          filename="package://Model_ver_2/meshes/link6.STL" />
      </geometry>
    </collision>
  </link>
  <joint
    name="joint6"
    type="revolute">
    <origin
      xyz="0 0.059156 0"
      rpy="1.5708 0.060371 -3.1416" />
    <parent
      link="link5" />
    <child
      link="link6" />
    <axis
      xyz="0 0 1" />
    <limit
      lower="-6.1087"
      upper="6.1087"
      effort="0"
      velocity="800" />
  </joint>
</robot>